
<sdf version="1.6">
    <model name="stiff_rope">
        <allow_auto_disable>true</allow_auto_disable>
        <pose frame="">0 0 0 0 0 0</pose>
        
        <link name="rope_link_1">
            <pose frame="">0.08 0 0 3.14159 -1.57079 3.14159</pose>
            <inertial>
                <pose frame="">0 0 0 0 0 0</pose>
                <mass>0.04
                </mass>
                <inertia>
                    <ixx>8.633333333333334e-05
                    </ixx>
                    <ixy>0</ixy>
                    <ixz>0</ixz>
                    <iyy>8.633333333333334e-05
                    </iyy>
                    <iyz>0</iyz>
                    <izz>2.0000000000000003e-06
                    </izz>
                </inertia>
            </inertial>
            <collision name="link_1_collision">
                <max_contacts>2</max_contacts>
                <pose frame="">0 0 0 0 0 0</pose>
                <geometry>
                    <cylinder>
                        <length>0.16</length>
                        <radius>0.01</radius>
                    </cylinder>
                </geometry>
                <surface>
                    <friction>
                        <ode>
                            <mu>10.00</mu>
                            <mu2>10.00</mu2>
                        </ode>
                    </friction>
                    <contact>
                        <ode>
                            <kp>1e15</kp>
                            <kd>1e11</kd>
                        </ode>
                    </contact>
                </surface>
            </collision>

            <collision name="link_1_collision_ball1">
                <max_contacts>2</max_contacts>
                <pose frame="">0 0 0.08 0 0 0</pose>
                <geometry>
                    <sphere>
                        <radius>0.01</radius>
                    </sphere>
                </geometry>
                <surface>
                    <friction>
                        <ode>
                            <mu>1.00</mu>
                            <mu2>1.00</mu2>
                        </ode>
                    </friction>
                    <contact>
                        <ode>
                            <kp>1e15</kp>
                            <kd>1e11</kd>
                        </ode>
                    </contact>
                </surface>
            </collision>

            <collision name="link_1_collision_ball2">
                <max_contacts>2</max_contacts>
                <pose frame="">0 0 -0.08 0 0 0</pose>
                <geometry>
                    <sphere>
                        <radius>0.01</radius>
                    </sphere>
                </geometry>
                <surface>
                    <friction>
                        <ode>
                            <mu>1.00</mu>
                            <mu2>1.00</mu2>
                        </ode>
                    </friction>
                    <contact>
                        <ode>
                            <kp>1e15</kp>
                            <kd>1e11</kd>
                        </ode>
                    </contact>
                </surface>
            </collision>

            <visual name="link_1_visual">
                <cast_shadows>0</cast_shadows>
                <pose frame="">0 0 0 0 0 0</pose>
                <geometry>
                    <cylinder>
                        <length>0.16
                        </length>
                        <radius>0.01
                        </radius>
                    </cylinder>
                </geometry>
                <material>
                    <script>
                        <name>Gazebo/Red</name>
                        <uri>file://media/materials/scripts/gazebo.material</uri>
                    </script>
                </material>
            </visual>
            <self_collide>1</self_collide>
        </link>
        
        <link name="rope_link_2">
            <pose frame="">0.24 0 0 3.14159 -1.57079 3.14159</pose>
            <inertial>
                <pose frame="">0 0 0 0 0 0</pose>
                <mass>0.04
                </mass>
                <inertia>
                    <ixx>8.633333333333334e-05
                    </ixx>
                    <ixy>0</ixy>
                    <ixz>0</ixz>
                    <iyy>8.633333333333334e-05
                    </iyy>
                    <iyz>0</iyz>
                    <izz>2.0000000000000003e-06
                    </izz>
                </inertia>
            </inertial>
            <collision name="link_2_collision">
                <max_contacts>2</max_contacts>
                <pose frame="">0 0 0 0 0 0</pose>
                <geometry>
                    <cylinder>
                        <length>0.16</length>
                        <radius>0.01</radius>
                    </cylinder>
                </geometry>
                <surface>
                    <friction>
                        <ode>
                            <mu>10.00</mu>
                            <mu2>10.00</mu2>
                        </ode>
                    </friction>
                    <contact>
                        <ode>
                            <kp>1e15</kp>
                            <kd>1e11</kd>
                        </ode>
                    </contact>
                </surface>
            </collision>

            <collision name="link_2_collision_ball1">
                <max_contacts>2</max_contacts>
                <pose frame="">0 0 0.08 0 0 0</pose>
                <geometry>
                    <sphere>
                        <radius>0.01</radius>
                    </sphere>
                </geometry>
                <surface>
                    <friction>
                        <ode>
                            <mu>1.00</mu>
                            <mu2>1.00</mu2>
                        </ode>
                    </friction>
                    <contact>
                        <ode>
                            <kp>1e15</kp>
                            <kd>1e11</kd>
                        </ode>
                    </contact>
                </surface>
            </collision>

            <collision name="link_2_collision_ball2">
                <max_contacts>2</max_contacts>
                <pose frame="">0 0 -0.08 0 0 0</pose>
                <geometry>
                    <sphere>
                        <radius>0.01</radius>
                    </sphere>
                </geometry>
                <surface>
                    <friction>
                        <ode>
                            <mu>1.00</mu>
                            <mu2>1.00</mu2>
                        </ode>
                    </friction>
                    <contact>
                        <ode>
                            <kp>1e15</kp>
                            <kd>1e11</kd>
                        </ode>
                    </contact>
                </surface>
            </collision>

            <visual name="link_2_visual">
                <cast_shadows>0</cast_shadows>
                <pose frame="">0 0 0 0 0 0</pose>
                <geometry>
                    <cylinder>
                        <length>0.16
                        </length>
                        <radius>0.01
                        </radius>
                    </cylinder>
                </geometry>
                <material>
                    <script>
                        <name>Gazebo/Red</name>
                        <uri>file://media/materials/scripts/gazebo.material</uri>
                    </script>
                </material>
            </visual>
            <self_collide>1</self_collide>
        </link>
        
        <link name="rope_link_3">
            <pose frame="">0.4 0 0 3.14159 -1.57079 3.14159</pose>
            <inertial>
                <pose frame="">0 0 0 0 0 0</pose>
                <mass>0.04
                </mass>
                <inertia>
                    <ixx>8.633333333333334e-05
                    </ixx>
                    <ixy>0</ixy>
                    <ixz>0</ixz>
                    <iyy>8.633333333333334e-05
                    </iyy>
                    <iyz>0</iyz>
                    <izz>2.0000000000000003e-06
                    </izz>
                </inertia>
            </inertial>
            <collision name="link_3_collision">
                <max_contacts>2</max_contacts>
                <pose frame="">0 0 0 0 0 0</pose>
                <geometry>
                    <cylinder>
                        <length>0.16</length>
                        <radius>0.01</radius>
                    </cylinder>
                </geometry>
                <surface>
                    <friction>
                        <ode>
                            <mu>10.00</mu>
                            <mu2>10.00</mu2>
                        </ode>
                    </friction>
                    <contact>
                        <ode>
                            <kp>1e15</kp>
                            <kd>1e11</kd>
                        </ode>
                    </contact>
                </surface>
            </collision>

            <collision name="link_3_collision_ball1">
                <max_contacts>2</max_contacts>
                <pose frame="">0 0 0.08 0 0 0</pose>
                <geometry>
                    <sphere>
                        <radius>0.01</radius>
                    </sphere>
                </geometry>
                <surface>
                    <friction>
                        <ode>
                            <mu>1.00</mu>
                            <mu2>1.00</mu2>
                        </ode>
                    </friction>
                    <contact>
                        <ode>
                            <kp>1e15</kp>
                            <kd>1e11</kd>
                        </ode>
                    </contact>
                </surface>
            </collision>

            <collision name="link_3_collision_ball2">
                <max_contacts>2</max_contacts>
                <pose frame="">0 0 -0.08 0 0 0</pose>
                <geometry>
                    <sphere>
                        <radius>0.01</radius>
                    </sphere>
                </geometry>
                <surface>
                    <friction>
                        <ode>
                            <mu>1.00</mu>
                            <mu2>1.00</mu2>
                        </ode>
                    </friction>
                    <contact>
                        <ode>
                            <kp>1e15</kp>
                            <kd>1e11</kd>
                        </ode>
                    </contact>
                </surface>
            </collision>

            <visual name="link_3_visual">
                <cast_shadows>0</cast_shadows>
                <pose frame="">0 0 0 0 0 0</pose>
                <geometry>
                    <cylinder>
                        <length>0.16
                        </length>
                        <radius>0.01
                        </radius>
                    </cylinder>
                </geometry>
                <material>
                    <script>
                        <name>Gazebo/Red</name>
                        <uri>file://media/materials/scripts/gazebo.material</uri>
                    </script>
                </material>
            </visual>
            <self_collide>1</self_collide>
        </link>
        
        <link name="rope_link_4">
            <pose frame="">0.5599999999999999 0 0 3.14159 -1.57079 3.14159</pose>
            <inertial>
                <pose frame="">0 0 0 0 0 0</pose>
                <mass>0.04
                </mass>
                <inertia>
                    <ixx>8.633333333333334e-05
                    </ixx>
                    <ixy>0</ixy>
                    <ixz>0</ixz>
                    <iyy>8.633333333333334e-05
                    </iyy>
                    <iyz>0</iyz>
                    <izz>2.0000000000000003e-06
                    </izz>
                </inertia>
            </inertial>
            <collision name="link_4_collision">
                <max_contacts>2</max_contacts>
                <pose frame="">0 0 0 0 0 0</pose>
                <geometry>
                    <cylinder>
                        <length>0.16</length>
                        <radius>0.01</radius>
                    </cylinder>
                </geometry>
                <surface>
                    <friction>
                        <ode>
                            <mu>10.00</mu>
                            <mu2>10.00</mu2>
                        </ode>
                    </friction>
                    <contact>
                        <ode>
                            <kp>1e15</kp>
                            <kd>1e11</kd>
                        </ode>
                    </contact>
                </surface>
            </collision>

            <collision name="link_4_collision_ball1">
                <max_contacts>2</max_contacts>
                <pose frame="">0 0 0.08 0 0 0</pose>
                <geometry>
                    <sphere>
                        <radius>0.01</radius>
                    </sphere>
                </geometry>
                <surface>
                    <friction>
                        <ode>
                            <mu>1.00</mu>
                            <mu2>1.00</mu2>
                        </ode>
                    </friction>
                    <contact>
                        <ode>
                            <kp>1e15</kp>
                            <kd>1e11</kd>
                        </ode>
                    </contact>
                </surface>
            </collision>

            <collision name="link_4_collision_ball2">
                <max_contacts>2</max_contacts>
                <pose frame="">0 0 -0.08 0 0 0</pose>
                <geometry>
                    <sphere>
                        <radius>0.01</radius>
                    </sphere>
                </geometry>
                <surface>
                    <friction>
                        <ode>
                            <mu>1.00</mu>
                            <mu2>1.00</mu2>
                        </ode>
                    </friction>
                    <contact>
                        <ode>
                            <kp>1e15</kp>
                            <kd>1e11</kd>
                        </ode>
                    </contact>
                </surface>
            </collision>

            <visual name="link_4_visual">
                <cast_shadows>0</cast_shadows>
                <pose frame="">0 0 0 0 0 0</pose>
                <geometry>
                    <cylinder>
                        <length>0.16
                        </length>
                        <radius>0.01
                        </radius>
                    </cylinder>
                </geometry>
                <material>
                    <script>
                        <name>Gazebo/Red</name>
                        <uri>file://media/materials/scripts/gazebo.material</uri>
                    </script>
                </material>
            </visual>
            <self_collide>1</self_collide>
        </link>
        
        <link name="rope_link_5">
            <pose frame="">0.72 0 0 3.14159 -1.57079 3.14159</pose>
            <inertial>
                <pose frame="">0 0 0 0 0 0</pose>
                <mass>0.04
                </mass>
                <inertia>
                    <ixx>8.633333333333334e-05
                    </ixx>
                    <ixy>0</ixy>
                    <ixz>0</ixz>
                    <iyy>8.633333333333334e-05
                    </iyy>
                    <iyz>0</iyz>
                    <izz>2.0000000000000003e-06
                    </izz>
                </inertia>
            </inertial>
            <collision name="link_5_collision">
                <max_contacts>2</max_contacts>
                <pose frame="">0 0 0 0 0 0</pose>
                <geometry>
                    <cylinder>
                        <length>0.16</length>
                        <radius>0.01</radius>
                    </cylinder>
                </geometry>
                <surface>
                    <friction>
                        <ode>
                            <mu>10.00</mu>
                            <mu2>10.00</mu2>
                        </ode>
                    </friction>
                    <contact>
                        <ode>
                            <kp>1e15</kp>
                            <kd>1e11</kd>
                        </ode>
                    </contact>
                </surface>
            </collision>

            <collision name="link_5_collision_ball1">
                <max_contacts>2</max_contacts>
                <pose frame="">0 0 0.08 0 0 0</pose>
                <geometry>
                    <sphere>
                        <radius>0.01</radius>
                    </sphere>
                </geometry>
                <surface>
                    <friction>
                        <ode>
                            <mu>1.00</mu>
                            <mu2>1.00</mu2>
                        </ode>
                    </friction>
                    <contact>
                        <ode>
                            <kp>1e15</kp>
                            <kd>1e11</kd>
                        </ode>
                    </contact>
                </surface>
            </collision>

            <collision name="link_5_collision_ball2">
                <max_contacts>2</max_contacts>
                <pose frame="">0 0 -0.08 0 0 0</pose>
                <geometry>
                    <sphere>
                        <radius>0.01</radius>
                    </sphere>
                </geometry>
                <surface>
                    <friction>
                        <ode>
                            <mu>1.00</mu>
                            <mu2>1.00</mu2>
                        </ode>
                    </friction>
                    <contact>
                        <ode>
                            <kp>1e15</kp>
                            <kd>1e11</kd>
                        </ode>
                    </contact>
                </surface>
            </collision>

            <visual name="link_5_visual">
                <cast_shadows>0</cast_shadows>
                <pose frame="">0 0 0 0 0 0</pose>
                <geometry>
                    <cylinder>
                        <length>0.16
                        </length>
                        <radius>0.01
                        </radius>
                    </cylinder>
                </geometry>
                <material>
                    <script>
                        <name>Gazebo/Red</name>
                        <uri>file://media/materials/scripts/gazebo.material</uri>
                    </script>
                </material>
            </visual>
            <self_collide>1</self_collide>
        </link>
        
        
        <joint name="joint_1" type="universal">
            <parent>rope_link_2</parent>
            <child>rope_link_1</child>
            <pose>0 0 -0.08 0 0 0</pose>
            <axis>
                <xyz>0 0.0 1.0</xyz>
                <dynamics>
                    <damping>0.01</damping>
                    <friction>1000000.0</friction>
                </dynamics>
                <use_parent_model_frame>1</use_parent_model_frame>
            </axis>
            <axis2>
                <xyz>0 1.0 6.123233995736766e-17</xyz>
                <dynamics>
                    <damping>0.01</damping>
                    <friction>1000000.0</friction>
                </dynamics>
                <use_parent_model_frame>1</use_parent_model_frame>
            </axis2>
            <physics>
                <ode>
                    <cfm>0.0005</cfm>
                </ode>
            </physics>
        </joint>
        
        <joint name="joint_2" type="universal">
            <parent>rope_link_3</parent>
            <child>rope_link_2</child>
            <pose>0 0 -0.08 0 0 0</pose>
            <axis>
                <xyz>0 0.0 1.0</xyz>
                <dynamics>
                    <damping>0.01</damping>
                    <friction>1000000.0</friction>
                </dynamics>
                <use_parent_model_frame>1</use_parent_model_frame>
            </axis>
            <axis2>
                <xyz>0 1.0 6.123233995736766e-17</xyz>
                <dynamics>
                    <damping>0.01</damping>
                    <friction>1000000.0</friction>
                </dynamics>
                <use_parent_model_frame>1</use_parent_model_frame>
            </axis2>
            <physics>
                <ode>
                    <cfm>0.0005</cfm>
                </ode>
            </physics>
        </joint>
        
        <joint name="joint_3" type="universal">
            <parent>rope_link_4</parent>
            <child>rope_link_3</child>
            <pose>0 0 -0.08 0 0 0</pose>
            <axis>
                <xyz>0 0.0 1.0</xyz>
                <dynamics>
                    <damping>0.01</damping>
                    <friction>1000000.0</friction>
                </dynamics>
                <use_parent_model_frame>1</use_parent_model_frame>
            </axis>
            <axis2>
                <xyz>0 1.0 6.123233995736766e-17</xyz>
                <dynamics>
                    <damping>0.01</damping>
                    <friction>1000000.0</friction>
                </dynamics>
                <use_parent_model_frame>1</use_parent_model_frame>
            </axis2>
            <physics>
                <ode>
                    <cfm>0.0005</cfm>
                </ode>
            </physics>
        </joint>
        
        <joint name="joint_4" type="universal">
            <parent>rope_link_5</parent>
            <child>rope_link_4</child>
            <pose>0 0 -0.08 0 0 0</pose>
            <axis>
                <xyz>0 0.0 1.0</xyz>
                <dynamics>
                    <damping>0.01</damping>
                    <friction>1000000.0</friction>
                </dynamics>
                <use_parent_model_frame>1</use_parent_model_frame>
            </axis>
            <axis2>
                <xyz>0 1.0 6.123233995736766e-17</xyz>
                <dynamics>
                    <damping>0.01</damping>
                    <friction>1000000.0</friction>
                </dynamics>
                <use_parent_model_frame>1</use_parent_model_frame>
            </axis2>
            <physics>
                <ode>
                    <cfm>0.0005</cfm>
                </ode>
            </physics>
        </joint>
        
        <link name='left_gripper'>
            <pose frame=''>0 0 0 0 0 0 </pose>
            <inertial>
                <pose frame=''>0 0 0 0 0 0</pose>
                <mass>0.001</mass>
                <inertia>
                    <ixx>0.000007</ixx>
                    <ixy>0</ixy>
                    <ixz>0</ixz>
                    <iyy>0.000007</iyy>
                    <iyz>0</iyz>
                    <izz>0.000007</izz>
                </inertia>
            </inertial>
            <collision name='left_gripper_collision'>
                <max_contacts>2</max_contacts>
                <pose frame=''>0 0 0 0 0 0</pose>
                <geometry>
                    <sphere>
                        <radius>0.01</radius>
                    </sphere>
                </geometry>
                <surface>
                    <friction>
                        <ode>
                            <mu>1.0</mu>
                            <mu2>1.0</mu2>
                        </ode>
                    </friction>
                    <contact>
                        <ode>
                        </ode>
                    </contact>
                </surface>
            </collision>
            <visual name='left_gripper_visual'>
                <cast_shadows>0</cast_shadows>
                <pose frame=''>0 0 0 0 0 0</pose>
                <geometry>
                    <sphere>
                        <radius>0.01</radius>
                    </sphere>
                </geometry>
                <material>
                    <script>
                        <name>Gazebo/Blue</name>
                        <uri>file://media/materials/scripts/gazebo.material</uri>
                    </script>
                </material>
            </visual>

            <self_collide>1</self_collide>
        </link>
        <joint name="left_gripper_joint" type="fixed">
            <child>left_gripper</child>
            <parent>rope_link_1</parent>
            <pose>0 0 0 0 0 0</pose>
            <physics>
                <ode>
                    <cfm>0.01</cfm>
                </ode>
            </physics>
        </joint>
        <link name='right_gripper'>
            <pose frame=''>0.8 0 0 0 0 0 </pose>
            <inertial>
                <pose frame=''>0 0 0 0 0 0</pose>
                <mass>0.001</mass>
                <inertia>
                    <ixx>0.000007</ixx>
                    <ixy>0</ixy>
                    <ixz>0</ixz>
                    <iyy>0.000007</iyy>
                    <iyz>0</iyz>
                    <izz>0.000007</izz>
                </inertia>
            </inertial>
            <collision name='right_gripper_collision'>
                <max_contacts>2</max_contacts>
                <pose frame=''>0 0 0 0 0 0</pose>
                <geometry>
                    <sphere>
                        <radius>0.01 </radius>
                    </sphere>
                </geometry>
                <surface>
                    <friction>
                        <ode>
                            <mu>1.0</mu>
                            <mu2>1.0</mu2>
                        </ode>
                    </friction>
                    <contact>
                        <ode>
                        </ode>
                    </contact>
                </surface>
            </collision>
            <visual name='right_gripper_visual'>
                <cast_shadows>0</cast_shadows>
                <pose frame=''>0 0 0 0 0 0</pose>
                <geometry>
                    <sphere>
                        <radius>0.01</radius>
                    </sphere>
                </geometry>
                <material>
                    <script>
                        <name>Gazebo/Yellow</name>
                        <uri>file://media/materials/scripts/gazebo.material</uri>
                    </script>
                </material>
            </visual>
            <self_collide>1</self_collide>
        </link>
        <joint name="right_gripper_joint" type="fixed">
            <parent>rope_link_5</parent>
            <child>right_gripper</child>
            <pose>0 0 0 0 0 0</pose>
            <physics>
                <ode>
                    <cfm>0.01</cfm>
                </ode>
            </physics>
        </joint>
        <plugin name='rope_plugin' filename='librope_plugin.so'>
            <num_links>5</num_links>
            <overstretching_factor>1.04</overstretching_factor>
        </plugin>
    </model>
</sdf>
